Traceback (most recent call last):
  File "/srv/conda/envs/notebook/lib/python3.12/site-packages/jupyter_cache/executors/utils.py", line 58, in single_nb_execution
    executenb(
  File "/srv/conda/envs/notebook/lib/python3.12/site-packages/nbclient/client.py", line 1319, in execute
    return NotebookClient(nb=nb, resources=resources, km=km, **kwargs).execute()
           ^^^^^^^^^^^^^^^^^^^^^^^^^^^^^^^^^^^^^^^^^^^^^^^^^^^^^^^^^^^^^^^^^^^^^
  File "/srv/conda/envs/notebook/lib/python3.12/site-packages/jupyter_core/utils/__init__.py", line 165, in wrapped
    return loop.run_until_complete(inner)
           ^^^^^^^^^^^^^^^^^^^^^^^^^^^^^^
  File "/srv/conda/envs/notebook/lib/python3.12/asyncio/base_events.py", line 691, in run_until_complete
    return future.result()
           ^^^^^^^^^^^^^^^
  File "/srv/conda/envs/notebook/lib/python3.12/site-packages/nbclient/client.py", line 709, in async_execute
    await self.async_execute_cell(
  File "/srv/conda/envs/notebook/lib/python3.12/site-packages/nbclient/client.py", line 1062, in async_execute_cell
    await self._check_raise_for_error(cell, cell_index, exec_reply)
  File "/srv/conda/envs/notebook/lib/python3.12/site-packages/nbclient/client.py", line 918, in _check_raise_for_error
    raise CellExecutionError.from_cell_and_msg(cell, exec_reply_content)
nbclient.exceptions.CellExecutionError: An error occurred while executing the following cell:
------------------
g = np.reshape(f, (8,9))
------------------


[0;31m---------------------------------------------------------------------------[0m
[0;31mValueError[0m                                Traceback (most recent call last)
Cell [0;32mIn[28], line 1[0m
[0;32m----> 1[0m g [38;5;241m=[39m [43mnp[49m[38;5;241;43m.[39;49m[43mreshape[49m[43m([49m[43mf[49m[43m,[49m[43m [49m[43m([49m[38;5;241;43m8[39;49m[43m,[49m[38;5;241;43m9[39;49m[43m)[49m[43m)[49m

File [0;32m/srv/conda/envs/notebook/lib/python3.12/site-packages/numpy/_core/fromnumeric.py:324[0m, in [0;36mreshape[0;34m(a, shape, order, newshape, copy)[0m
[1;32m    322[0m [38;5;28;01mif[39;00m copy [38;5;129;01mis[39;00m [38;5;129;01mnot[39;00m [38;5;28;01mNone[39;00m:
[1;32m    323[0m     [38;5;28;01mreturn[39;00m _wrapfunc(a, [38;5;124m'[39m[38;5;124mreshape[39m[38;5;124m'[39m, shape, order[38;5;241m=[39morder, copy[38;5;241m=[39mcopy)
[0;32m--> 324[0m [38;5;28;01mreturn[39;00m [43m_wrapfunc[49m[43m([49m[43ma[49m[43m,[49m[43m [49m[38;5;124;43m'[39;49m[38;5;124;43mreshape[39;49m[38;5;124;43m'[39;49m[43m,[49m[43m [49m[43mshape[49m[43m,[49m[43m [49m[43morder[49m[38;5;241;43m=[39;49m[43morder[49m[43m)[49m

File [0;32m/srv/conda/envs/notebook/lib/python3.12/site-packages/numpy/_core/fromnumeric.py:57[0m, in [0;36m_wrapfunc[0;34m(obj, method, *args, **kwds)[0m
[1;32m     54[0m     [38;5;28;01mreturn[39;00m _wrapit(obj, method, [38;5;241m*[39margs, [38;5;241m*[39m[38;5;241m*[39mkwds)
[1;32m     56[0m [38;5;28;01mtry[39;00m:
[0;32m---> 57[0m     [38;5;28;01mreturn[39;00m [43mbound[49m[43m([49m[38;5;241;43m*[39;49m[43margs[49m[43m,[49m[43m [49m[38;5;241;43m*[39;49m[38;5;241;43m*[39;49m[43mkwds[49m[43m)[49m
[1;32m     58[0m [38;5;28;01mexcept[39;00m [38;5;167;01mTypeError[39;00m:
[1;32m     59[0m     [38;5;66;03m# A TypeError occurs if the object does have such a method in its[39;00m
[1;32m     60[0m     [38;5;66;03m# class, but its signature is not identical to that of NumPy's. This[39;00m
[0;32m   (...)[0m
[1;32m     64[0m     [38;5;66;03m# Call _wrapit from within the except clause to ensure a potential[39;00m
[1;32m     65[0m     [38;5;66;03m# exception has a traceback chain.[39;00m
[1;32m     66[0m     [38;5;28;01mreturn[39;00m _wrapit(obj, method, [38;5;241m*[39margs, [38;5;241m*[39m[38;5;241m*[39mkwds)

[0;31mValueError[0m: cannot reshape array of size 5000 into shape (8,9)

